Workbook
Name Listarefin: OFFSET('Range Refin'!$D$2,0,0,COUNTIF('Range Refin'!$D$2:$D$32,">"&0),1)

Sheet Resumo
B2: Valores Entrada | I2: Resultados Saída
R3: Refin da Port
D4: Convênio | E4: Siape | R4: Refin de Carteira
D5: Produto | E5: Refin da Port | K5: Troco: | L5: =('Dados de entrada'!B24+'Dados de entrada'!B33+'Dados de entrada'!B42+'Dados de entrada'!B51)-('Dados de entrada'!K4+'Dados de entrada'!K5) -> 22302.791
D6: Com Seguro? | E6: Não | K6: Taxa Ponderada: | L6: =ROUND('Dados de entrada'!B53,4) -> 0.0252
D7: Data do Contrato | E7: =+TODAY() -> 46212 | P7: Comissão
D8: Primeiro Vencimento Estimado | E8: 46241 | P8: {=IF(E6="Sim", _xlfn.XLOOKUP(Apoio!$K$2, _xlfn._xlws.SORT(_xlfn._xlws.FILTER('Tabela de Comissionamento'!$C$2:$C$109, 'Tabela de Comissionamento'!$A$2:$A$109=IFERROR(_xlfn.XLOOKUP(Apoio!$K$1,Apoio!$D$2:$D$23,Apoio!$E$2:$E$23),Apoio!$K$1))), _xlfn._xlws.SORT(_xlfn._xlws.FILTER('Tabela de Comissionamento'!$D$2:$D$109, 'Tabela de Comissionamento'!$A$2:$A$109=IFERROR(_xlfn.XLOOKUP(Apoio!$K$1,Apoio!$D$2:$D$23,Apoio!$E$2:$E$23),Apoio!$K$1))), "",-1), _xlfn.XLOOKUP(Apoio!$K$2, _xlfn._xlws.SORT(_xlfn._xlws.FILTER('Tabela de Comissionamento'!$B$2:$B$109, 'Tabela de Comissionamento'!$A$2:$A$109=IFERROR(_xlfn.XLOOKUP(Apoio!$K$1,Apoio!$D$2:$D$23,Apoio!$E$2:$E$23),Apoio!$K$1))), _xlfn._xlws.SORT(_xlfn._xlws.FILTER('Tabela de Comissionamento'!$D$2:$D$109, 'Tabela de Comissionamento'!$A$2:$A$109=IFERROR(_xlfn.XLOOKUP(Apoio!$K$1,Apoio!$D$2:$D$23,Apoio!$E$2:$E$23),Apoio!$K$1))), "",-1))} -> Tabela 6
K9: Taxa Ponderada Mín - Refin da Port | L9: =IF($E$6="Sim", SUMIFS(Apoio!$G:$G,Apoio!$D:$D,$E$4,Apoio!$F:$F,$R$3)-0.03%, SUMIFS(Apoio!$G:$G,Apoio!$D:$D,$E$4,Apoio!$F:$F,$R$3)) -> 0.0167
D10: Prazo Refin (meses) | E10: 120 | K10: A carência impacta o cálculo da taxa ponderada.
D11: Taxa Refin (a.m) | E11: 0.028
D12: PMT Refin* | E12: 3000
D13: *Se PMT Refin for igual à da Portabilidade, repetir o valor na célula acima
D14: =IF(Apoio!$K$6="Não Favorável", "Taxa ponderada fora do range permitido para "&Apoio!$K$1, "Range permitido: "&TEXT(Apoio!$K$4,"0,00%")&" a "&TEXT(Apoio!$K$5,"0,00%")) -> Taxa ponderada fora do range permitido para Siape
I15: Resultados Estimados*
D17: Contrato 1
D18: Saldo Contrato portado | E18: 90000
D19: Prazo Remanescente (meses) | E19: 50 | K19: =IF(AND(OR($E$4="Marinha",$E$4="Exército",$E$4="Aeronáutica"),$E$6="Sim"),"Parecer: Não Favorável - Seguro não disponível","Parecer: "&Apoio!$K$6) -> Parecer: Não Favorável
D20: PMT Portabilidade | E20: 3000 | K20: =IF(AND(OR($E$4="Marinha",$E$4="Exército",$E$4="Aeronáutica"),$E$6="Sim"),"",IF(Apoio!$K$6="Não Favorável","",P8&" de comissionamento"))
D22: Contrato 2
D23: Saldo Contrato portado | E23: 0.0182
D24: Prazo Remanescente | E24: =+PV(E23,E19,-E20) -> 97939.922
D25: PMT Portabilidade
D27: Contrato 3
D28: Saldo Contrato portado
D29: Prazo Remanescente
D30: PMT Portabilidade
D32: Contrato 4
D33: Saldo Contrato portado
D34: Prazo Remanescente
D35: PMT Portabilidade

Sheet Dia de Vencimento
A1: Convênio | B1: Órgão | C1: Situação | D1: Dia de Vencimento
A2: Estado de Minas Gerais | B2: Bombeiros | C2: Ativo | D2: 7
A3: Estado de Minas Gerais | B3: Defensoria Publica MG | C3: Ativo | D3: 7
A4: Estado de Minas Gerais | B4: IPSEMG | C4: Ativo | D4: 7
A5: Estado de Minas Gerais | B5: IPSM | C5: Ativo | D5: 7
A6: Estado de Minas Gerais | B6: PMMG | C6: Ativo | D6: 7
A7: Estado de Minas Gerais | B7: SEPLAG | C7: Ativo | D7: 7
A8: TJMG | B8: TJMG | C8: Ativo | D8: 21
A9: Servidor Federal (SIAPE) | B9: Servidor Federal (SIAPE) | C9: Ativo | D9: 12
A10: Pref Belo Horizonte | B10: Pref de Belo Horizonte | C10: Ativo | D10: 25
A11: INSS | B11: INSS | C11: Ativo | D11: 7
A12: Estado de Sao Paulo | B12: Estado de Sao Paulo - SEFAZ | C12: Ativo | D12: 8
A13: Estado de Sao Paulo | B13: CPA PM do Estado de Sao Paulo - PMESP | C13: Ativo | D13: 8
... A62: Ministerio Publico do Estado de Mato Grosso do Sul | B62: MINISTERIO PÚBLICO DO ESTADO DE MATO GROSSO DO SUL | C62: Ativo | D62: 12

Sheet Range Refin
A1: S/ Seguro | B1: C/ Seguro | D1: Tabela Selecionada
A2: =IF(Resumo!$E$4="Siape", 0.018, IF(Resumo!$E$4="INSS", 0.0185, 0.03)) -> 0.018 | B2: =IF(A2="", "", A2-0.03%) -> 0.0177 | D2: =IF(A2="", "", IF(Resumo!$E$6="Não", A2, B2)) -> 0.018
A3: =IF(A2="", "", IF(A2-0.05%>=0.015, A2-0.05%, "")) -> 0.0175 | B3: =IF(A3="", "", A3-0.03%) -> 0.0172 | D3: =IF(A3="", "", IF(Resumo!$E$6="Não", A3, B3)) -> 0.0175
A4: =IF(A3="", "", IF(A3-0.05%>=0.015, A3-0.05%, "")) -> 0.017 | B4: =IF(A4="", "", A4-0.03%) -> 0.0167 | D4: =IF(A4="", "", IF(Resumo!$E$6="Não", A4, B4)) -> 0.017
A5: =IF(A4="", "", IF(A4-0.05%>=0.015, A4-0.05%, "")) -> 0.0165 | B5: =IF(A5="", "", A5-0.03%) -> 0.0162 | D5: =IF(A5="", "", IF(Resumo!$E$6="Não", A5, B5)) -> 0.0165
A6: =IF(A5="", "", IF(A5-0.05%>=0.015, A5-0.05%, "")) -> 0.016 | B6: =IF(A6="", "", A6-0.03%) -> 0.0157 | D6: =IF(A6="", "", IF(Resumo!$E$6="Não", A6, B6)) -> 0.016
A7: =IF(A6="", "", IF(A6-0.05%>=0.015, A6-0.05%, "")) -> 0.0155 | B7: =IF(A7="", "", A7-0.03%) -> 0.0152 | D7: =IF(A7="", "", IF(Resumo!$E$6="Não", A7, B7)) -> 0.0155
A8: =IF(A7="", "", IF(A7-0.05%>=0.015, A7-0.05%, "")) -> 0.015 | B8: =IF(A8="", "", A8-0.03%) -> 0.0147 | D8: =IF(A8="", "", IF(Resumo!$E$6="Não", A8, B8)) -> 0.015
A9: =IF(A8="", "", IF(A8-0.05%>=0.015, A8-0.05%, "")) | B9: =IF(A9="", "", A9-0.03%) | D9: =IF(A9="", "", IF(Resumo!$E$6="Não", A9, B9))
A10: =IF(A9="", "", IF(A9-0.05%>=0.015, A9-0.05%, "")) | B10: =IF(A10="", "", A10-0.03%) | D10: =IF(A10="", "", IF(Resumo!$E$6="Não", A10, B10))
A11: =IF(A10="", "", IF(A10-0.05%>=0.015, A10-0.05%, "")) | B11: =IF(A11="", "", A11-0.03%) | D11: =IF(A11="", "", IF(Resumo!$E$6="Não", A11, B11))
A12: =IF(A11="", "", IF(A11-0.05%>=0.015, A11-0.05%, "")) | B12: =IF(A12="", "", A12-0.03%) | D12: =IF(A12="", "", IF(Resumo!$E$6="Não", A12, B12))
A13: =IF(A12="", "", IF(A12-0.05%>=0.015, A12-0.05%, "")) | B13: =IF(A13="", "", A13-0.03%) | D13: =IF(A13="", "", IF(Resumo!$E$6="Não", A13, B13))
A14: =IF(A13="", "", IF(A13-0.05%>=0.015, A13-0.05%, "")) | B14: =IF(A14="", "", A14-0.03%) | D14: =IF(A14="", "", IF(Resumo!$E$6="Não", A14, B14))
... A32: =IF(A31="", "", IF(A31-0.05%>=0.015, A31-0.05%, "")) | B32: =IF(A32="", "", A32-0.03%) | D32: =IF(A32="", "", IF(Resumo!$E$6="Não", A32, B32))

Sheet Dados de entrada
A1: Dados de entrada (Operação) | D1: Dados de entrada (Viabilidade) | G1: Custos da operação | J1: Resultados finais | M1: Viabilidade
A2: Valor da PMT | B2: =+IF(AND(Resumo!E18>0,OR(Resumo!E23>0,Resumo!E28>0,Resumo!E33>0)),Resumo!E20+Resumo!E25+Resumo!E30+Resumo!E35,Resumo!E12) -> 3000 | D2: Nº PMT liq. Antecipada | E2: 18 | G2: Custo de OP | H2: 0 | J2: Valor PMT | K2: =+B2 -> 3000 | M2: XVPL | N2: =XNPV('Dados de entrada'!H10,INDIRECT("'Fluxo detalhado'!R3:R"&B10+3),INDIRECT("'Fluxo detalhado'!B3:B"&B10+3)) -> 135284.92
A3: Refins (normais) | B3: =B23+B32+B41+B50 -> 90000.018 | D3: % liq. Antecipada | E3: 0 | G3: Custos marginais | H3: 531.02 | J3: Valor total financiado | K3: =((B2/(B6/(1-(1/((1+B6)^B10)))))/((1+B6)^((B9-30)/30))) -> 113220.08 | M3: XTIR | N3: =XIRR(INDIRECT("'Fluxo detalhado'!r3:r"&B10+3),INDIRECT("'Fluxo detalhado'!B3:B"&B10+3)) -> 0.32168388
A4: Refins (portabilidades) | B4: 0 | D4: % inadimplência | E4: 0.0202 | G4: Total desp. marginais | H4: =H2+H3 -> 531.02 | J4: Valor IOF | K4: =SUM('Fluxo detalhado'!I4:I147) -> 776.54119 | M4: Rentabilidade (a.a.) | N4: =(1+N3)/(1+'Dados de entrada'!H10)-1 -> 0.235565
A5: Tarifas | B5: 0 | D5: CDI Curva (a.a.) | E5: 0.0697 | G5: Custo de linha fixo (R$) | H5: 0 | J5: Valor do Seguro | K5: =((E55-K4)/(1+B14))*B14 -> 0
A6: Taxa desejada | B6: =B53 -> 0.025202067 | D6: Custo Curva (% CDI) | E6: 1 | G6: Custo de linha variável (%) | H6: 0 | J6: =A5 -> Tarifas | K6: =B5 -> 0
A7: Data do contrato | B7: =Resumo!E7 -> 46212 | D7: Convênio | E7: INSS | G7: Outras desp. Operac. | H7: ='Dados de entrada'!E12 -> 0 | J7: Soma dos refinanciamentos | K7: =B3+B4 -> 90000.018
A8: Primeiro vencimento | B8: =Resumo!E8 -> 46241 | D8: Banco para saque OP | E8: Bancoob | G8: ='Dados de entrada'!D5 -> CDI Curva (a.a.) | H8: ='Dados de entrada'!E5 -> 0.0697 | J8: Vlr líquido da operação | K8: =K3-K4-K6-K7-K5 -> 22443.518
A9: Carência (real) | B9: =DAYS360(B7,B8) -> 28 | D9: Comissão a vista | E9: 0 | G9: ='Dados de entrada'!D6 -> Custo Curva (% CDI) | H9: ='Dados de entrada'!E6 -> 1 | J9: =A13 -> Regularização contratos | K9: =B13 -> 0 | M9: =K3-K4-K5-K6 -> 112443.54
A10: Prazo | B10: =Resumo!E10 -> 120 | D10: Comissão no fluxo | E10: 0 | G10: Custo operação (a.a.) | H10: =H8*H9 -> 0.0697 | J10: Vlr liberado ao cliente | K10: =K8-K9 -> 22443.518
A11: Alíquota IOF (ao dia) | B11: 8.2e-05 | D11: Valor a comissionar | E11: 0 | G11: =D14 -> Despesas com RCO | H11: =IF(B4=0,0,E14) -> 0 | J11: TIR (ao ano) | K11: =XIRR(INDIRECT("'Fluxo detalhado'!K3:K"&B10+3),INDIRECT("'Fluxo detalhado'!B3:B"&B10+3)) -> 0.34748717
A12: Alíquota IOF (adicional) | B12: 0.0038 | D12: Despesas operacionais | E12: 0 | J12: TIR (ao mês) | K12: =((((K11)+1)^(1/12))-1) -> 0.02516488
A13: Regularização contratos | B13: 0 | D13: Base cálc. Comissão | E13: =IF(E11=1,K8,K8+B4) -> 22443.518 | J13: CET (ao ano) | K13: =XIRR(INDIRECT("'Fluxo detalhado'!J3:J"&B10+3),INDIRECT("'Fluxo detalhado'!B3:B"&B10+3)) -> 0.3507431
A14: Alíquota Seguro | B14: =+IF(Resumo!$E$6="Sim",$B$57,0) -> 0 | D14: Despesas com RCO | E14: 0 | J14: Valor total financiado - tx. ponderada | K14: =+SUM(B23:B24,B32:B33,B41:B42,B50:B51) -> 113079.35
D15: Duration (em dias) | E15: =ROUND(SUM('Fluxo detalhado'!U4:U122)/(K3-B3),0) -> 1016
A17: Contrato 1
A18: Prazo Remanescente Port | B18: =Resumo!E19 -> 50 | K18: =+K3-K7 -> 23220.06
A19: Taxa Contrato Port | B19: =RATE(B18,-B20,B23) -> 0.022230322 | D19: =(1+B19)^12-1 -> 0.30192242
A20: PMT Port | B20: =+Resumo!E20 -> 3000 | D20: 4740.81 | G20: =+RATE(29,-712.96,16455.25) -> 0.015928655 | H20: PMT | J20: =(B6/(1-(1/((1+B6)^ B10))))*((K3-B3)*((1+B6)^((B9-30)/30))) -> 615.26348
A21: PMT Refin da Port | B21: =+Resumo!E12 -> 3000 | D21: =+RATE(B18,-B20,D20) -> #NUM!
A22: Taxa Refin da Port | B22: =+Resumo!E11 -> 0.028 | D22: =(1+B22)^12-1 -> 0.39289178
A23: Saldo Devedor Port | B23: =+Resumo!E18 -> 90000
A24: Troco | B24: =+-'Fluxo detalhado'!AC3 -> 23079.332
A26: Contrato 2
A27: Prazo Remanescente Port | B27: =+Resumo!E24 -> 97939.922
A28: Taxa Contrato Port | B28: =RATE(B27,-B29,B32) -> #NUM!
A29: PMT Port | B29: =+Resumo!E25 -> 0
A30: PMT Refin da Port | B30: =+Resumo!E25 -> 0
A31: Taxa Refin da Port | D31: =(1+B31)^12-1 -> 0
A32: Saldo Devedor Port | B32: =+Resumo!E23 -> 0.0182
A33: Troco | B33: =-'Fluxo detalhado'!AF3 -> 0
A35: Contrato 3
A36: Prazo Remanescente Port | B36: =+Resumo!E29 -> 0
A37: Taxa Contrato Port | B37: =RATE(B36,-B38,B41) -> #NUM!
A38: PMT Port | B38: =+Resumo!E30 -> 0
A39: PMT Refin da Port | B39: =B38 -> 0
A40: Taxa Refin da Port | D40: =(1+B40)^12-1 -> 0
A41: Saldo Devedor Port | B41: =+Resumo!E28 -> 0
A42: Troco | B42: =+-'Fluxo detalhado'!AI3 -> 0
A44: Contrato 4
...

Sheet Fluxo detalhado
A1: Fluxo estimado / provisório | T1: =SUM(T4:T116) -> 22694.263 | U1: =SUM(U4:U116)/T1 -> 1008.9935 | AB1: Contrato 1 | AE1: Contrato 2 | AH1: Contrato 3 | AK1: Contrato 4 | AW1: Taxa Ponderada
A2: N | B2: Data | C2: Dias correção | D2: Saldo inicial | E2: PMT PROVISÓRIA | F2: Saldo final | G2: Vlr amortizado | H2: Dias corridos | I2: IOF | J2: Cálculo CET | K2: Cálculo TIR | L2: Viab. PMT | M2: Viab. Perda | N2: Viab. Comissão | O2: Saldo dev. c/ antec. | P2: PIS/Cofins | Q2: Custo de linha | R2: Fluxo de caixa | S2: Dias Acumulados | T2: VP | U2: Duration | V2: PMT | X2: DIF PMT | AA2: Dias Acumulados | AB2: Fluxo Port | AC2: Fluxo Refin | AD2: VP Fluxo Refin | AE2: Fluxo Port | AF2: Fluxo Refin | AG2: VP Fluxo Refin | AH2: Fluxo Port | AI2: Fluxo Refin | AJ2: VP Fluxo Refin | AK2: Fluxo Port | AL2: Fluxo Refin | AM2: VP Fluxo Refin | AN2: Fluxo Consolidado | AW2: TIR a.a | AX2: TIR a.m
A3: 0 | B3: ='Dados de entrada'!B7 -> 46212 | D3: ='Dados de entrada'!K3-'Dados de entrada'!B3 -> 23220.06 | J3: ='Dados de entrada'!K8+'Dados de entrada'!K7 -> 112443.54 | K3: ='Dados de entrada'!K3 -> 113220.08 | N3: ='Dados de entrada'!E13*'Dados de entrada'!E9 -> 0 | O3: ='Dados de entrada'!K3 -> 113220.08 | R3: =-'Dados de entrada'!B3-'Dados de entrada'!B4-'Dados de entrada'!K8-'Dados de entrada'!K4-'Dados de entrada'!H4-'Dados de entrada'!H7-'Dados de entrada'!E9*'Dados de entrada'!E13+'Dados de entrada'!B5-'Dados de entrada'!H11-'Dados de entrada'!K5 -> -113751.1 | Y3: =B3 -> 46212 | AB3: =-'Dados de entrada'!B23 -> -90000 | AC3: =-SUM(AD4:AD147) -> -23079.332 | AE3: =-'Dados de entrada'!B32 -> -0.0182 | AF3: =-SUM(AG4:AG99) -> 0 | AH3: =+-'Dados de entrada'!B41 -> 0 | AI3: =-SUM(AJ4:AJ99) -> 0 | AK3: =+-'Dados de entrada'!B50 -> 0 | AL3: =-SUM(AM4:AM99) -> 0 | AN3: =SUM(AB3:AC3,AE3:AF3,AH3:AI3,AK3:AL3) -> -113079.35 | AW3: =XIRR(AN3:AN147,Y3:Y147) -> 0.34807383 | AX3: =(1+AW3)^(1/12)-1 -> 0.025202067
A4: 1 | B4: ='Dados de entrada'!B8 -> 46241 | C4: ='Dados de entrada'!B9 -> 28 | D4: =D3*(1+'Dados de entrada'!$B$6)^((C4)/30) -> 23765.785 | E4: =-'Dados de entrada'!J20 -> -615.26348 | F4: =D4+E4 -> 23150.522 | G4: =D3-F4 -> 69.537643 | H4: =B4-$B$3 -> 29 | I4: =MIN(H4,365)*G4*'Dados de entrada'!$B$11+G4*'Dados de entrada'!$B$12 -> 0.42960356 | J4: =V4 -> -3000 | K4: =V4 -> -3000 | L4: =IF(A4<='Dados de entrada'!$J$2,-V4,-V4*(1-'Dados de entrada'!$J$3)) -> 3000 | M4: =L4*'Dados de entrada'!$E$4 -> 60.6 | N4: =IF(A4<='Dados de entrada'!$E$2,'Dados de entrada'!$E$13*'Dados de entrada'!$E$10/'Dados de entrada'!$B$10,'Dados de entrada'!$E$13*'Dados de entrada'!$E$10/'Dados de entrada'!$B$10*(1-'Dados de entrada'!$E$3)) -> 0 | O4: =IF(AND(A4='Dados de entrada'!$E$2),(O3*(1+'Dados de entrada'!$B$6)-L4)*(1-'Dados de entrada'!$E$3),IF(AND(A4<>'Dados de entrada'!$A$2),O3*(1+'Dados de entrada'!$B$6)^(C4/30)-L4,"")) -> 112881.02 | P4: =(O3*((1+'Dados de entrada'!$B$6)^(-DAYS360(B4,B3)/30)-1)-O3*((1+'Dados de entrada'!$H$10)^(-DAYS360(B4,B3)/360)-1))*4.65% -> 96.071171 | Q4: =IF(E4<>"",'Dados de entrada'!$H$5-E4*'Dados de entrada'!$H$6,"") -> 0 | R4: =IF(A4='Dados de entrada'!$E$2,PV('Dados de entrada'!$B$6,'Dados de entrada'!$B$10-'Dados de entrada'!$E$2+1,+L4*(-'Dados de entrada'!$E$3),,1)+L4*(1-'Dados de entrada'!$E$3)-M4-N4-P4-Q4,L4-M4-N4-P4-Q4) -> 2843.3288 | S4: =IF(H4<>"",H4,"") -> 29 | T4: =IF(E4<>"",(-E4)/((1+'Dados de entrada'!$B$6)^(S4/30)),"") -> 600.63686 | U4: =IF(T4<>"",T4*S4,"") -> 17418.469 | V4: =-'Dados de entrada'!B2 -> -3000 | X4: =+Resumo!$E$12-Resumo!$E$20 -> 0 | Y4: =B4 -> 46241 | AA4: =C4 -> 28 | AB4: =IF(A4<='Dados de entrada'!$B$18,'Dados de entrada'!$B$20,0) -> 3000 | AC4: =IF(OR(Resumo!$E$23>0,Resumo!$E$28>0,Resumo!$E$33>0),IF(AND(A4>'Dados de entrada'!$B$18,A4<='Dados de entrada'!$B$10),'Dados de entrada'!$B$21,0),IF(AND(A4>'Dados de entrada'!$B$18,A4<='Dados de entrada'!$B$10),'Dados de entrada'!$B$21,IF(A4<='Dados de entrada'!$B$18,X4,0))) -> 0 | AD4: =AC4/((1+'Dados de entrada'!$D$22)^($AA4/360)) -> 0 | AE4: =IF(A4<='Dados de entrada'!$B$27,'Dados de entrada'!$B$29,0) -> 0 | AF4: =IF(AND(A4>'Dados de entrada'!$B$27,A4<='Dados de entrada'!$B$10),'Dados de entrada'!$B$30,0) -> 0 | AG4: =AF4/((1+'Dados de entrada'!$D$31)^($AA4/360)) -> 0 | AH4: =IF(A4<='Dados de entrada'!$B$36,'Dados de entrada'!$B$38,0) -> 0 | AI4: =IF(AND(A4>'Dados de entrada'!$B$36,A4<='Dados de entrada'!$B$10),'Dados de entrada'!$B$39,0) -> 0 | AJ4: =AI4/((1+'Dados de entrada'!$D$40)^($AA4/360)) -> 0 | AK4: =IF(A4<='Dados de entrada'!$B$45,'Dados de entrada'!$B$47,0) -> 0 | AL4: =IF(AND(A4>'Dados de entrada'!$B$45,A4<='Dados de entrada'!$B$10),'Dados de entrada'!$B$48,0) -> 0 | AM4: =AL4/((1+'Dados de entrada'!$D$49)^($AA4/360)) -> 0 | AN4: =SUM(AB4:AC4,AE4:AF4,AH4:AI4,AK4:AL4) -> 3000
A5: =IF(A4="","",IF(A4+1<='Dados de entrada'!$B$10,A4+1,"")) -> 2 | B5: =IF(A5="","",DATE(YEAR(B4),MONTH(B4)+1,DAY(B4))) -> 46272 | C5: =IF(A5="","",30) -> 30 | D5: =IF(A5="","",F4*(1+'Dados de entrada'!$B$6)^(C5/30)) -> 23733.963 | E5: =IF(A5="","",-'Dados de entrada'!$J$20) -> -615.26348 | F5: =IF(A5="","",D5+E5) -> 23118.699 | G5: =IF(A5="","",F4-F5) -> 31.822465 | H5: =IF(A5="","",B5-$B$3) -> 60 | I5: =IF(A5="","",MIN(H5,365)*G5*'Dados de entrada'!$B$11+G5*'Dados de entrada'!$B$12) -> 0.27749189 | J5: =IF(A5="","",V5) -> -3000 | K5: =IF(A5="","",V5) -> -3000 | L5: =IF(A5="","",IF(A5<='Dados de entrada'!$J$2,-V4,-V4*(1-'Dados de entrada'!$J$3))) -> 3000 | M5: =IF(A5="","",L5*'Dados de entrada'!$E$4) -> 60.6 | N5: =IF(A5="","",IF(A5<='Dados de entrada'!$E$2,'Dados de entrada'!$E$13*'Dados de entrada'!$E$10/'Dados de entrada'!$B$10,'Dados de entrada'!$E$13*'Dados de entrada'!$E$10/'Dados de entrada'!$B$10*(1-'Dados de entrada'!$E$3))) -> 0 | O5: =IF(A5="","",IF(AND(A5='Dados de entrada'!$E$2),(O4*(1+'Dados de entrada'!$B$6)-L5)*(1-'Dados de entrada'!$E$3),IF(AND(A5<>'Dados de entrada'!$A$2),O4*(1+'Dados de entrada'!$B$6)^(C5/30)-L5,""))) -> 112725.85 | P5: =IF(A5="","",(O4*((1+'Dados de entrada'!$B$6)^(-DAYS360(B5,B4)/30)-1)-O4*((1+'Dados de entrada'!$H$10)^(-DAYS360(B5,B4)/360)-1))*4.65%) -> 102.72975 | Q5: =IF(E5<>"",'Dados de entrada'!$H$5-E5*'Dados de entrada'!$H$6,"") -> 0 | R5: =IF(A5="","",IF(A5='Dados de entrada'!$E$2,PV('Dados de entrada'!$B$6,'Dados de entrada'!$B$10-'Dados de entrada'!$E$2+1,+L5*(-'Dados de entrada'!$E$3),,1)+L5*(1-'Dados de entrada'!$E$3)-M5-N5-P5-Q5,L5-M5-N5-P5-Q5)) -> 2836.6703 | S5: =IF(H5<>"",H5,"") -> 60 | T5: =IF(E5<>"",(-E5)/((1+'Dados de entrada'!$B$6)^(S5/30)),"") -> 585.38581 | U5: =IF(T5<>"",T5*S5,"") -> 35123.148 | V5: =IF(F5="","",-'Dados de entrada'!$B$2) -> -3000 | X5: =+Resumo!$E$12-Resumo!$E$20 -> 0 | Y5: =EDATE(Y4,1) -> 46272 | Z5: 30 | AA5: =AA4+Z5 -> 58 | AB5: =IF(A5<='Dados de entrada'!$B$18,'Dados de entrada'!$B$20,0) -> 3000 | AC5: =IF(OR(Resumo!$E$23>0,Resumo!$E$28>0,Resumo!$E$33>0),IF(AND(A5>'Dados de entrada'!$B$18,A5<='Dados de entrada'!$B$10),'Dados de entrada'!$B$21,0),IF(AND(A5>'Dados de entrada'!$B$18,A5<='Dados de entrada'!$B$10),'Dados de entrada'!$B$21,IF(A5<='Dados de entrada'!$B$18,X5,0))) -> 0 | AD5: =AC5/((1+'Dados de entrada'!$D$22)^($AA5/360)) -> 0 | AE5: =IF(A5<='Dados de entrada'!$B$27,'Dados de entrada'!$B$29,0) -> 0 | AF5: =IF(AND(A5>'Dados de entrada'!$B$27,A5<='Dados de entrada'!$B$10),'Dados de entrada'!$B$30,0) -> 0 | AG5: =AF5/((1+'Dados de entrada'!$D$31)^($AA5/360)) -> 0 | AH5: =IF(A5<='Dados de entrada'!$B$36,'Dados de entrada'!$B$38,0) -> 0 | AI5: =IF(AND(A5>'Dados de entrada'!$B$36,A5<='Dados de entrada'!$B$10),'Dados de entrada'!$B$39,0) -> 0 | AJ5: =AI5/((1+'Dados de entrada'!$D$40)^($AA5/360)) -> 0 | AK5: =IF(A5<='Dados de entrada'!$B$45,'Dados de entrada'!$B$47,0) -> 0 | AL5: =IF(AND(A5>'Dados de entrada'!$B$45,A5<='Dados de entrada'!$B$10),'Dados de entrada'!$B$48,0) -> 0 | AM5: =AL5/((1+'Dados de entrada'!$D$49)^($AA5/360)) -> 0 | AN5: =SUM(AB5:AC5,AE5:AF5,AH5:AI5,AK5:AL5) -> 3000
A6: =IF(A5="","",IF(A5+1<='Dados de entrada'!$B$10,A5+1,"")) -> 3 | B6: =IF(A6="","",DATE(YEAR(B5),MONTH(B5)+1,DAY(B5))) -> 46302 | C6: =IF(A6="","",30) -> 30 | D6: =IF(A6="","",F5*(1+'Dados de entrada'!$B$6)^(C6/30)) -> 23701.338 | E6: =IF(A6="","",-'Dados de entrada'!$J$20) -> -615.26348 | F6: =IF(A6="","",D6+E6) -> 23086.075 | G6: =IF(A6="","",F5-F6) -> 32.624457 | H6: =IF(A6="","",B6-$B$3) -> 90 | I6: =IF(A6="","",MIN(H6,365)*G6*'Dados de entrada'!$B$11+G6*'Dados de entrada'!$B$12) -> 0.36474143 | J6: =IF(A6="","",V6) -> -3000 | K6: =IF(A6="","",V6) -> -3000 | L6: =IF(A6="","",IF(A6<='Dados de entrada'!$J$2,-V5,-V5*(1-'Dados de entrada'!$J$3))) -> 3000 | M6: =IF(A6="","",L6*'Dados de entrada'!$E$4) -> 60.6 | N6: =IF(A6="","",IF(A6<='Dados de entrada'!$E$2,'Dados de entrada'!$E$13*'Dados de entrada'!$E$10/'Dados de entrada'!$B$10,'Dados de entrada'!$E$13*'Dados de entrada'!$E$10/'Dados de entrada'!$B$10*(1-'Dados de entrada'!$E$3))) -> 0 | O6: =IF(A6="","",IF(AND(A6='Dados de entrada'!$E$2),(O5*(1+'Dados de entrada'!$B$6)-L6)*(1-'Dados de entrada'!$E$3),IF(AND(A6<>'Dados de entrada'!$A$2),O5*(1+'Dados de entrada'!$B$6)^(C6/30)-L6,""))) -> 112566.77 | P6: =IF(A6="","",(O5*((1+'Dados de entrada'!$B$6)^(-DAYS360(B6,B5)/30)-1)-O5*((1+'Dados de entrada'!$H$10)^(-DAYS360(B6,B5)/360)-1))*4.65%) -> 102.58854 | Q6: =IF(E6<>"",'Dados de entrada'!$H$5-E6*'Dados de entrada'!$H$6,"") -> 0 | R6: =IF(A6="","",IF(A6='Dados de entrada'!$E$2,PV('Dados de entrada'!$B$6,'Dados de entrada'!$B$10-'Dados de entrada'!$E$2+1,+L6*(-'Dados de entrada'!$E$3),,1)+L6*(1-'Dados de entrada'!$E$3)-M6-N6-P6-Q6,L6-M6-N6-P6-Q6)) -> 2836.8115 | S6: =IF(H6<>"",H6,"") -> 90 | T6: =IF(E6<>"",(-E6)/((1+'Dados de entrada'!$B$6)^(S6/30)),"") -> 570.99554 | U6: =IF(T6<>"",T6*S6,"") -> 51389.599 | V6: =IF(F6="","",-'Dados de entrada'!$B$2) -> -3000 | X6: =+Resumo!$E$12-Resumo!$E$20 -> 0 | Y6: =EDATE(Y5,1) -> 46302 | Z6: 30 | AA6: =AA5+Z6 -> 88 | AB6: =IF(A6<='Dados de entrada'!$B$18,'Dados de entrada'!$B$20,0) -> 3000 | AC6: =IF(OR(Resumo!$E$23>0,Resumo!$E$28>0,Resumo!$E$33>0),IF(AND(A6>'Dados de entrada'!$B$18,A6<='Dados de entrada'!$B$10),'Dados de entrada'!$B$21,0),IF(AND(A6>'Dados de entrada'!$B$18,A6<='Dados de entrada'!$B$10),'Dados de entrada'!$B$21,IF(A6<='Dados de entrada'!$B$18,X6,0))) -> 0 | AD6: =AC6/((1+'Dados de entrada'!$D$22)^($AA6/360)) -> 0 | AE6: =IF(A6<='Dados de entrada'!$B$27,'Dados de entrada'!$B$29,0) -> 0 | AF6: =IF(AND(A6>'Dados de entrada'!$B$27,A6<='Dados de entrada'!$B$10),'Dados de entrada'!$B$30,0) -> 0 | AG6: =AF6/((1+'Dados de entrada'!$D$31)^($AA6/360)) -> 0 | AH6: =IF(A6<='Dados de entrada'!$B$36,'Dados de entrada'!$B$38,0) -> 0 | AI6: =IF(AND(A6>'Dados de entrada'!$B$36,A6<='Dados de entrada'!$B$10),'Dados de entrada'!$B$39,0) -> 0 | AJ6: =AI6/((1+'Dados de entrada'!$D$40)^($AA6/360)) -> 0 | AK6: =IF(A6<='Dados de entrada'!$B$45,'Dados de entrada'!$B$47,0) -> 0 | AL6: =IF(AND(A6>'Dados de entrada'!$B$45,A6<='Dados de entrada'!$B$10),'Dados de entrada'!$B$48,0) -> 0 | AM6: =AL6/((1+'Dados de entrada'!$D$49)^($AA6/360)) -> 0 | AN6: =SUM(AB6:AC6,AE6:AF6,AH6:AI6,AK6:AL6) -> 3000
A7: =IF(A6="","",IF(A6+1<='Dados de entrada'!$B$10,A6+1,"")) -> 4 | B7: =IF(A7="","",DATE(YEAR(B6),MONTH(B6)+1,DAY(B6))) -> 46333 | C7: =IF(A7="","",30) -> 30 | D7: =IF(A7="","",F6*(1+'Dados de entrada'!$B$6)^(C7/30)) -> 23667.892 | E7: =IF(A7="","",-'Dados de entrada'!$J$20) -> -615.26348 | F7: =IF(A7="","",D7+E7) -> 23052.628 | G7: =IF(A7="","",F6-F7) -> 33.446661 | H7: =IF(A7="","",B7-$B$3) -> 121 | I7: =IF(A7="","",MIN(H7,365)*G7*'Dados de entrada'!$B$11+G7*'Dados de entrada'!$B$12) -> 0.45895508 | J7: =IF(A7="","",V7) -> -3000 | K7: =IF(A7="","",V7) -> -3000 | L7: =IF(A7="","",IF(A7<='Dados de entrada'!$J$2,-V6,-V6*(1-'Dados de entrada'!$J$3))) -> 3000 | M7: =IF(A7="","",L7*'Dados de entrada'!$E$4) -> 60.6 | N7: =IF(A7="","",IF(A7<='Dados de entrada'!$E$2,'Dados de entrada'!$E$13*'Dados de entrada'!$E$10/'Dados de entrada'!$B$10,'Dados de entrada'!$E$13*'Dados de entrada'!$E$10/'Dados de entrada'!$B$10*(1-'Dados de entrada'!$E$3))) -> 0 | O7: =IF(A7="","",IF(AND(A7='Dados de entrada'!$E$2),(O6*(1+'Dados de entrada'!$B$6)-L7)*(1-'Dados de entrada'!$E$3),IF(AND(A7<>'Dados de entrada'!$A$2),O6*(1+'Dados de entrada'!$B$6)^(C7/30)-L7,""))) -> 112403.69 | P7: =IF(A7="","",(O6*((1+'Dados de entrada'!$B$6)^(-DAYS360(B7,B6)/30)-1)-O6*((1+'Dados de entrada'!$H$10)^(-DAYS360(B7,B6)/360)-1))*4.65%) -> 102.44377 | Q7: =IF(E7<>"",'Dados de entrada'!$H$5-E7*'Dados de entrada'!$H$6,"") -> 0 | R7: =IF(A7="","",IF(A7='Dados de entrada'!$E$2,PV('Dados de entrada'!$B$6,'Dados de entrada'!$B$10-'Dados de entrada'!$E$2+1,+L7*(-'Dados de entrada'!$E$3),,1)+L7*(1-'Dados de entrada'!$E$3)-M7-N7-P7-Q7,L7-M7-N7-P7-Q7)) -> 2836.9562 | S7: =IF(H7<>"",H7,"") -> 121 | T7: =IF(E7<>"",(-E7)/((1+'Dados de entrada'!$B$6)^(S7/30)),"") -> 556.49713 | U7: =IF(T7<>"",T7*S7,"") -> 67336.152 | V7: =IF(F7="","",-'Dados de entrada'!$B$2) -> -3000 | X7: =+Resumo!$E$12-Resumo!$E$20 -> 0 | Y7: =EDATE(Y6,1) -> 46333 | Z7: 30 | AA7: =AA6+Z7 -> 118 | AB7: =IF(A7<='Dados de entrada'!$B$18,'Dados de entrada'!$B$20,0) -> 3000 | AC7: =IF(OR(Resumo!$E$23>0,Resumo!$E$28>0,Resumo!$E$33>0),IF(AND(A7>'Dados de entrada'!$B$18,A7<='Dados de entrada'!$B$10),'Dados de entrada'!$B$21,0),IF(AND(A7>'Dados de entrada'!$B$18,A7<='Dados de entrada'!$B$10),'Dados de entrada'!$B$21,IF(A7<='Dados de entrada'!$B$18,X7,0))) -> 0 | AD7: =AC7/((1+'Dados de entrada'!$D$22)^($AA7/360)) -> 0 | AE7: =IF(A7<='Dados de entrada'!$B$27,'Dados de entrada'!$B$29,0) -> 0 | AF7: =IF(AND(A7>'Dados de entrada'!$B$27,A7<='Dados de entrada'!$B$10),'Dados de entrada'!$B$30,0) -> 0 | AG7: =AF7/((1+'Dados de entrada'!$D$31)^($AA7/360)) -> 0 | AH7: =IF(A7<='Dados de entrada'!$B$36,'Dados de entrada'!$B$38,0) -> 0 | AI7: =IF(AND(A7>'Dados de entrada'!$B$36,A7<='Dados de entrada'!$B$10),'Dados de entrada'!$B$39,0) -> 0 | AJ7: =AI7/((1+'Dados de entrada'!$D$40)^($AA7/360)) -> 0 | AK7: =IF(A7<='Dados de entrada'!$B$45,'Dados de entrada'!$B$47,0) -> 0 | AL7: =IF(AND(A7>'Dados de entrada'!$B$45,A7<='Dados de entrada'!$B$10),'Dados de entrada'!$B$48,0) -> 0 | AM7: =AL7/((1+'Dados de entrada'!$D$49)^($AA7/360)) -> 0 | AN7: =SUM(AB7:AC7,AE7:AF7,AH7:AI7,AK7:AL7) -> 3000
A8: =IF(A7="","",IF(A7+1<='Dados de entrada'!$B$10,A7+1,"")) -> 5 | B8: =IF(A8="","",DATE(YEAR(B7),MONTH(B7)+1,DAY(B7))) -> 46363 | C8: =IF(A8="","",30) -> 30 | D8: =IF(A8="","",F7*(1+'Dados de entrada'!$B$6)^(C8/30)) -> 23633.602 | E8: =IF(A8="","",-'Dados de entrada'!$J$20) -> -615.26348 | F8: =IF(A8="","",D8+E8) -> 23018.339 | G8: =IF(A8="","",F7-F8) -> 34.289586 | H8: =IF(A8="","",B8-$B$3) -> 151 | I8: =IF(A8="","",MIN(H8,365)*G8*'Dados de entrada'!$B$11+G8*'Dados de entrada'!$B$12) -> 0.55487407 | J8: =IF(A8="","",V8) -> -3000 | K8: =IF(A8="","",V8) -> -3000 | L8: =IF(A8="","",IF(A8<='Dados de entrada'!$J$2,-V7,-V7*(1-'Dados de entrada'!$J$3))) -> 3000 | M8: =IF(A8="","",L8*'Dados de entrada'!$E$4) -> 60.6 | N8: =IF(A8="","",IF(A8<='Dados de entrada'!$E$2,'Dados de entrada'!$E$13*'Dados de entrada'!$E$10/'Dados de entrada'!$B$10,'Dados de entrada'!$E$13*'Dados de entrada'!$E$10/'Dados de entrada'!$B$10*(1-'Dados de entrada'!$E$3))) -> 0 | O8: =IF(A8="","",IF(AND(A8='Dados de entrada'!$E$2),(O7*(1+'Dados de entrada'!$B$6)-L8)*(1-'Dados de entrada'!$E$3),IF(AND(A8<>'Dados de entrada'!$A$2),O7*(1+'Dados de entrada'!$B$6)^(C8/30)-L8,""))) -> 112236.5 | P8: =IF(A8="","",(O7*((1+'Dados de entrada'!$B$6)^(-DAYS360(B8,B7)/30)-1)-O7*((1+'Dados de entrada'!$H$10)^(-DAYS360(B8,B7)/360)-1))*4.65%) -> 102.29535 | Q8: =IF(E8<>"",'Dados de entrada'!$H$5-E8*'Dados de entrada'!$H$6,"") -> 0 | R8: =IF(A8="","",IF(A8='Dados de entrada'!$E$2,PV('Dados de entrada'!$B$6,'Dados de entrada'!$B$10-'Dados de entrada'!$E$2+1,+L8*(-'Dados de entrada'!$E$3),,1)+L8*(1-'Dados de entrada'!$E$3)-M8-N8-P8-Q8,L8-M8-N8-P8-Q8)) -> 2837.1047 | S8: =IF(H8<>"",H8,"") -> 151 | T8: =IF(E8<>"",(-E8)/((1+'Dados de entrada'!$B$6)^(S8/30)),"") -> 542.81702 | U8: =IF(T8<>"",T8*S8,"") -> 81965.369 | V8: =IF(F8="","",-'Dados de entrada'!$B$2) -> -3000 | X8: =+Resumo!$E$12-Resumo!$E$20 -> 0 | Y8: =EDATE(Y7,1) -> 46363 | Z8: 30 | AA8: =AA7+Z8 -> 148 | AB8: =IF(A8<='Dados de entrada'!$B$18,'Dados de entrada'!$B$20,0) -> 3000 | AC8: =IF(OR(Resumo!$E$23>0,Resumo!$E$28>0,Resumo!$E$33>0),IF(AND(A8>'Dados de entrada'!$B$18,A8<='Dados de entrada'!$B$10),'Dados de entrada'!$B$21,0),IF(AND(A8>'Dados de entrada'!$B$18,A8<='Dados de entrada'!$B$10),'Dados de entrada'!$B$21,IF(A8<='Dados de entrada'!$B$18,X8,0))) -> 0 | AD8: =AC8/((1+'Dados de entrada'!$D$22)^($AA8/360)) -> 0 | AE8: =IF(A8<='Dados de entrada'!$B$27,'Dados de entrada'!$B$29,0) -> 0 | AF8: =IF(AND(A8>'Dados de entrada'!$B$27,A8<='Dados de entrada'!$B$10),'Dados de entrada'!$B$30,0) -> 0 | AG8: =AF8/((1+'Dados de entrada'!$D$31)^($AA8/360)) -> 0 | AH8: =IF(A8<='Dados de entrada'!$B$36,'Dados de entrada'!$B$38,0) -> 0 | AI8: =IF(AND(A8>'Dados de entrada'!$B$36,A8<='Dados de entrada'!$B$10),'Dados de entrada'!$B$39,0) -> 0 | AJ8: =AI8/((1+'Dados de entrada'!$D$40)^($AA8/360)) -> 0 | AK8: =IF(A8<='Dados de entrada'!$B$45,'Dados de entrada'!$B$47,0) -> 0 | AL8: =IF(AND(A8>'Dados de entrada'!$B$45,A8<='Dados de entrada'!$B$10),'Dados de entrada'!$B$48,0) -> 0 | AM8: =AL8/((1+'Dados de entrada'!$D$49)^($AA8/360)) -> 0 | AN8: =SUM(AB8:AC8,AE8:AF8,AH8:AI8,AK8:AL8) -> 3000
A9: =IF(A8="","",IF(A8+1<='Dados de entrada'!$B$10,A8+1,"")) -> 6 | B9: =IF(A9="","",DATE(YEAR(B8),MONTH(B8)+1,DAY(B8))) -> 46394 | C9: =IF(A9="","",30) -> 30 | D9: =IF(A9="","",F8*(1+'Dados de entrada'!$B$6)^(C9/30)) -> 23598.448 | E9: =IF(A9="","",-'Dados de entrada'!$J$20) -> -615.26348 | F9: =IF(A9="","",D9+E9) -> 22983.185 | G9: =IF(A9="","",F8-F9) -> 35.153754 | H9: =IF(A9="","",B9-$B$3) -> 182 | I9: =IF(A9="","",MIN(H9,365)*G9*'Dados de entrada'!$B$11+G9*'Dados de entrada'!$B$12) -> 0.65821889 | J9: =IF(A9="","",V9) -> -3000 | K9: =IF(A9="","",V9) -> -3000 | L9: =IF(A9="","",IF(A9<='Dados de entrada'!$J$2,-V8,-V8*(1-'Dados de entrada'!$J$3))) -> 3000 | M9: =IF(A9="","",L9*'Dados de entrada'!$E$4) -> 60.6 | N9: =IF(A9="","",IF(A9<='Dados de entrada'!$E$2,'Dados de entrada'!$E$13*'Dados de entrada'!$E$10/'Dados de entrada'!$B$10,'Dados de entrada'!$E$13*'Dados de entrada'!$E$10/'Dados de entrada'!$B$10*(1-'Dados de entrada'!$E$3))) -> 0 | O9: =IF(A9="","",IF(AND(A9='Dados de entrada'!$E$2),(O8*(1+'Dados de entrada'!$B$6)-L9)*(1-'Dados de entrada'!$E$3),IF(AND(A9<>'Dados de entrada'!$A$2),O8*(1+'Dados de entrada'!$B$6)^(C9/30)-L9,""))) -> 112065.09 | P9: =IF(A9="","",(O8*((1+'Dados de entrada'!$B$6)^(-DAYS360(B9,B8)/30)-1)-O8*((1+'Dados de entrada'!$H$10)^(-DAYS360(B9,B8)/360)-1))*4.65%) -> 102.14319 | Q9: =IF(E9<>"",'Dados de entrada'!$H$5-E9*'Dados de entrada'!$H$6,"") -> 0 | R9: =IF(A9="","",IF(A9>'Dados de entrada'!$E$2,PV('Dados de entrada'!$B$6,'Dados de entrada'!$B$10-'Dados de entrada'!$E$2+1,+L9*(-'Dados de entrada'!$E$3),,1)+L9*(1-'Dados de entrada'!$E$3)-M9-N9-P9-Q9,L9-M9-N9-P9-Q9)) -> 2837.2568 | S9: =IF(H9<>"",H9,"") -> 182 | T9: =IF(E9<>"",(-E9)/((1+'Dados de entrada'!$B$6)^(S9/30)),"") -> 529.0341 | U9: =IF(T9<>"",T9*S9,"") -> 96284.206 | V9: =IF(F9="","",-'Dados de entrada'!$B$2) -> -3000 | X9: =+Resumo!$E$12-Resumo!$E$20 -> 0 | Y9: =EDATE(Y8,1) -> 46394 | Z9: 30 | AA9: =AA8+Z9 -> 178 | AB9: =IF(A9<='Dados de entrada'!$B$18,'Dados de entrada'!$B$20,0) -> 3000 | AC9: =IF(OR(Resumo!$E$23>0,Resumo!$E$28>0,Resumo!$E$33>0),IF(AND(A9>'Dados de entrada'!$B$18,A9<='Dados de entrada'!$B$10),'Dados de entrada'!$B$21,0),IF(AND(A9>'Dados de entrada'!$B$18,A9<='Dados de entrada'!$B$10),'Dados de entrada'!$B$21,IF(A9<='Dados de entrada'!$B$18,X9,0))) -> 0 | AD9: =AC9/((1+'Dados de entrada'!$D$22)^($AA9/360)) -> 0 | AE9: =IF(A9<='Dados de entrada'!$B$27,'Dados de entrada'!$B$29,0) -> 0 | AF9: =IF(AND(A9>'Dados de entrada'!$B$27,A9<='Dados de entrada'!$B$10),'Dados de entrada'!$B$30,0) -> 0 | AG9: =AF9/((1+'Dados de entrada'!$D$31)^($AA9/360)) -> 0 | AH9: =IF(A9<='Dados de entrada'!$B$36,'Dados de entrada'!$B$38,0) -> 0 | AI9: =IF(AND(A9>'Dados de entrada'!$B$36,A9<='Dados de entrada'!$B$10),'Dados de entrada'!$B$39,0) -> 0 | AJ9: =AI9/((1+'Dados de entrada'!$D$40)^($AA9/360)) -> 0 | AK9: =IF(A9<='Dados de entrada'!$B$45,'Dados de entrada'!$B$47,0) -> 0 | AL9: =IF(AND(A9>'Dados de entrada'!$B$45,A9<='Dados de entrada'!$B$10),'Dados de entrada'!$B$48,0) -> 0 | AM9: =AL9/((1+'Dados de entrada'!$D$49)^($AA9/360)) -> 0 | AN9: =SUM(AB9:AC9,AE9:AF9,AH9:AI9,AK9:AL9) -> 3000
A10: =IF(A9="","",IF(A9+1<='Dados de entrada'!$B$10,A9+1,"")) -> 7 | B10: =IF(A10="","",DATE(YEAR(B9),MONTH(B9)+1,DAY(B9))) -> 46425 | C10: =IF(A10="","",30) -> 30 | D10: =IF(A10="","",F9*(1+'Dados de entrada'!$B$6)^(C10/30)) -> 23562.409 | E10: =IF(A10="","",-'Dados de entrada'!$J$20) -> -615.26348 | F10: =IF(A10="","",D10+E10) -> 22947.145 | G10: =IF(A10="","",F9-F10) -> 36.039701 | H10: =IF(A10="","",B10-$B$3) -> 213 | I10: =IF(A10="","",MIN(H10,365)*G10*'Dados de entrada'!$B$11+G10*'Dados de entrada'!$B$12) -> 0.76642029 | J10: =IF(A10="","",V10) -> -3000 | K10: =IF(A10="","",V10) -> -3000 | L10: =IF(A10="","",IF(A10<='Dados de entrada'!$J$2,-V9,-V9*(1-'Dados de entrada'!$J$3))) -> 3000 | M10: =IF(A10="","",L10*'Dados de entrada'!$E$4) -> 60.6 | N10: =IF(A10="","",IF(A10<='Dados de entrada'!$E$2,'Dados de entrada'!$E$13*'Dados de entrada'!$E$10/'Dados de entrada'!$B$10,'Dados de entrada'!$E$13*'Dados de entrada'!$E$10/'Dados de entrada'!$B$10*(1-'Dados de entrada'!$E$3))) -> 0 | O10: =IF(A10="","",IF(AND(A10='Dados de entrada'!$E$2),(O9*(1+'Dados de entrada'!$B$6)-L10)*(1-'Dados de entrada'!$E$3),IF(AND(A10<>'Dados de entrada'!$A$2),O9*(1+'Dados de entrada'!$B$6)^(C10/30)-L10,""))) -> 111889.36 | P10: =IF(A10="","",(O9*((1+'Dados de entrada'!$B$6)^(-DAYS360(B10,B9)/30)-1)-O9*((1+'Dados de entrada'!$H$10)^(-DAYS360(B10,B9)/360)-1))*4.65%) -> 101.9872 | Q10: =IF(E10<>"",'Dados de entrada'!$H$5-E10*'Dados de entrada'!$H$6,"") -> 0 | R10: =IF(A10="","",IF(A10='Dados de entrada'!$E$2,PV('Dados de entrada'!$B$6,'Dados de entrada'!$B$10-'Dados de entrada'!$E$2+1,+L10*(-'Dados de entrada'!$E$3),,1)+L10*(1-'Dados de entrada'!$E$3)-M10-N10-P10-Q10,L10-M10-N10-P10-Q10)) -> 2837.4128 | S10: =IF(H10<>"",H10,"") -> 213 | T10: =IF(E10<>"",(-E10)/((1+'Dados de entrada'!$B$6)^(S10/30)),"") -> 515.60115 | U10: =IF(T10<>"",T10*S10,"") -> 109823.04 | V10: =IF(F10="","",-'Dados de entrada'!$B$2) -> -3000 | X10: =+Resumo!$E$12-Resumo!$E$20 -> 0 | Y10: =EDATE(Y9,1) -> 46425 | Z10: 30 | AA10: =AA9+Z10 -> 208 | AB10: =IF(A10<='Dados de entrada'!$B$18,'Dados de entrada'!$B$20,0) -> 3000 | AC10: =IF(OR(Resumo!$E$23>0,Resumo!$E$28>0,Resumo!$E$33>0),IF(AND(A10>'Dados de entrada'!$B$18,A10<='Dados de entrada'!$B$10),'Dados de entrada'!$B$21,0),IF(AND(A10>'Dados de entrada'!$B$18,A10<='Dados de entrada'!$B$10),'Dados de entrada'!$B$21,IF(A10<='Dados de entrada'!$B$18,X10,0))) -> 0 | AD10: =AC10/((1+'Dados de entrada'!$D$22)^($AA10/360)) -> 0 | AE10: =IF(A10<='Dados de entrada'!$B$27,'Dados de entrada'!$B$29,0) -> 0 | AF10: =IF(AND(A10>'Dados de entrada'!$B$27,A10<='Dados de entrada'!$B$10),'Dados de entrada'!$B$30,0) -> 0 | AG10: =AF10/((1+'Dados de entrada'!$D$31)^($AA10/360)) -> 0 | AH10: =IF(A10<='Dados de entrada'!$B$36,'Dados de entrada'!$B$38,0) -> 0 | AI10: =IF(AND(A10>'Dados de entrada'!$B$36,A10<='Dados de entrada'!$B$10),'Dados de entrada'!$B$39,0) -> 0 | AJ10: =AI10/((1+'Dados de entrada'!$D$40)^($AA10/360)) -> 0 | AK10: =IF(A10<='Dados de entrada'!$B$45,'Dados de entrada'!$B$47,0) -> 0 | AL10: =IF(AND(A10>'Dados de entrada'!$B$45,A10<='Dados de entrada'!$B$10),'Dados de entrada'!$B$48,0) -> 0 | AM10: =AL10/((1+'Dados de entrada'!$D$49)^($AA10/360)) -> 0 | AN10: =SUM(AB10:AC10,AE10:AF10,AH10:AI10,AK10:AL10) -> 3000
A11: =IF(A10="","",IF(A10+1<='Dados de entrada'!$B$10,A10+1,"")) -> 8 | B11: =IF(A11="","",DATE(YEAR(B10),MONTH(B10)+1,DAY(B10))) -> 46453 | C11: =IF(A11="","",30) -> 30 | D11: =IF(A11="","",F10*(1+'Dados de entrada'!$B$6)^(C11/30)) -> 23525.461 | E11: =IF(A11="","",-'Dados de entrada'!$J$20) -> -615.26348 | F11: =IF(A11="","",D11+E11) -> 22910.197 | G11: =IF(A11="","",F10-F11) -> 36.947976 | H11: =IF(A11="","",B11-$B$3) -> 241 | I11: =IF(A11="","",MIN(H11,365)*G11*'Dados de entrada'!$B$11+G11*'Dados de entrada'!$B$12) -> 0.87056822 | J11: =IF(A11="","",V11) -> -3000 | K11: =IF(A11="","",V11) -> -3000 | L11: =IF(A11="","",IF(A11<='Dados de entrada'!$J$2,-V10,-V10*(1-'Dados de entrada'!$J$3))) -> 3000 | M11: =IF(A11="","",L11*'Dados de entrada'!$E$4) -> 60.6 | N11: =IF(A11="","",IF(A11<='Dados de entrada'!$E$2,'Dados de entrada'!$E$13*'Dados de entrada'!$E$10/'Dados de entrada'!$B$10,'Dados de entrada'!$E$13*'Dados de entrada'!$E$10/'Dados de entrada'!$B$10*(1-'Dados de entrada'!$E$3))) -> 0 | O11: =IF(A11="","",IF(AND(A11='Dados de entrada'!$E$2),(O10*(1+'Dados de entrada'!$B$6)-L11)*(1-'Dados de entrada'!$E$3),IF(AND(A11<>'Dados de entrada'!$A$2),O10*(1+'Dados de entrada'!$B$6)^(C11/30)-L11,""))) -> 111709.2 | P11: =IF(A11="","",(O10*((1+'Dados de entrada'!$B$6)^(-DAYS360(B11,B10)/30)-1)-O10*((1+'Dados de entrada'!$H$10)^(-DAYS360(B11,B10)/360)-1))*4.65%) -> 101.82727 | Q11: =IF(E11<>"",'Dados de entrada'!$H$5-E11*'Dados de entrada'!$H$6,"") -> 0 | R11: =IF(A11="","",IF(A11='Dados de entrada'!$E$2,PV('Dados de entrada'!$B$6,'Dados de entrada'!$B$10-'Dados de entrada'!$E$2+1,+L11*(-'Dados de entrada'!$E$3),,1)+L11*(1-'Dados de entrada'!$E$3)-M11-N11-P11-Q11,L11-M11-N11-P11-Q11)) -> 2837.5727 | S11: =IF(H11<>"",H11,"") -> 241 | T11: =IF(E11<>"",(-E11)/((1+'Dados de entrada'!$B$6)^(S11/30)),"") -> 503.76157 | U11: =IF(T11<>"",T11*S11,"") -> 121406.54 | V11: =IF(F11="","",-'Dados de entrada'!$B$2) -> -3000 | X11: =+Resumo!$E$12-Resumo!$E$20 -> 0 | Y11: =EDATE(Y10,1) -> 46453 | Z11: 30 | AA11: =AA10+Z11 -> 238 | AB11: =IF(A11<='Dados de entrada'!$B$18,'Dados de entrada'!$B$20,0) -> 3000 | AC11: =IF(OR(Resumo!$E$23>0,Resumo!$E$28>0,Resumo!$E$33>0),IF(AND(A11>'Dados de entrada'!$B$18,A11<='Dados de entrada'!$B$10),'Dados de entrada'!$B$21,0),IF(AND(A11>'Dados de entrada'!$B$18,A11<='Dados de entrada'!$B$10),'Dados de entrada'!$B$21,IF(A11<='Dados de entrada'!$B$18,X11,0))) -> 0 | AD11: =AC11/((1+'Dados de entrada'!$D$22)^($AA11/360)) -> 0 | AE11: =IF(A11<='Dados de entrada'!$B$27,'Dados de entrada'!$B$29,0) -> 0 | AF11: =IF(AND(A11>'Dados de entrada'!$B$27,A11<='Dados de entrada'!$B$10),'Dados de entrada'!$B$30,0) -> 0 | AG11: =AF11/((1+'Dados de entrada'!$D$31)^($AA11/360)) -> 0 | AH11: =IF(A11<='Dados de entrada'!$B$36,'Dados de entrada'!$B$38,0) -> 0 | AI11: =IF(AND(A11>'Dados de entrada'!$B$36,A11<='Dados de entrada'!$B$10),'Dados de entrada'!$B$39,0) -> 0 | AJ11: =AI11/((1+'Dados de entrada'!$D$40)^($AA11/360)) -> 0 | AK11: =IF(A11<='Dados de entrada'!$B$45,'Dados de entrada'!$B$47,0) -> 0 | AL11: =IF(AND(A11>'Dados de entrada'!$B$45,A11<='Dados de entrada'!$B$10),'Dados de entrada'!$B$48,0) -> 0 | AM11: =AL11/((1+'Dados de entrada'!$D$49)^($AA11/360)) -> 0 | AN11: =SUM(AB11:AC11,AE11:AF11,AH11:AI11,AK11:AL11) -> 3000
A12: =IF(A11="","",IF(A11+1<='Dados de entrada'!$B$10,A11+1,"")) -> 9 | B12: =IF(A12="","",DATE(YEAR(B11),MONTH(B11)+1,DAY(B11))) -> 46484 | C12: =IF(A12="","",30) -> 30 | D12: =IF(A12="","",F11*(1+'Dados de entrada'!$B$6)^(C12/30)) -> 23487.582 | E12: =IF(A12="","",-'Dados de entrada'!$J$20) -> -615.26348 | F12: =IF(A12="","",D12+E12) -> 22872.318 | G12: =IF(A12="","",F11-F12) -> 37.879142 | H12: =IF(A12="","",B12-$B$3) -> 272 | I12: =IF(A12="","",MIN(H12,365)*G12*'Dados de entrada'!$B$11+G12*'Dados de entrada'!$B$12) -> 0.98879711 | J12: =IF(A12="","",V12) -> -3000 | K12: =IF(A12="","",V12) -> -3000 | L12: =IF(A12="","",IF(A12<='Dados de entrada'!$J$2,-V11,-V11*(1-'Dados de entrada'!$J$3))) -> 3000 | M12: =IF(A12="","",L12*'Dados de entrada'!$E$4) -> 60.6 | N12: =IF(A12="","",IF(A12<='Dados de entrada'!$E$2,'Dados de entrada'!$E$13*'Dados de entrada'!$E$10/'Dados de entrada'!$B$10,'Dados de entrada'!$E$13*'Dados de entrada'!$E$10/'Dados de entrada'!$B$10*(1-'Dados de entrada'!$E$3))) -> 0 | O12: =IF(A12="","",IF(AND(A12='Dados de entrada'!$E$2),(O11*(1+'Dados de entrada'!$B$6)-L12)*(1-'Dados de entrada'!$E$3),IF(AND(A12<>'Dados de entrada'!$A$2),O11*(1+'Dados de entrada'!$B$6)^(C12/30)-L12,""))) -> 111524.5 | P12: =IF(A12="","",(O11*((1+'Dados de entrada'!$B$6)^(-DAYS360(B12,B11)/30)-1)-O11*((1+'Dados de entrada'!$H$10)^(-DAYS360(B12,B11)/360)-1))*4.65%) -> 101.66332 | Q12: =IF(E12<>"",'Dados de entrada'!$H$5-E12*'Dados de entrada'!$H$6,"") -> 0 | R12: =IF(A12="","",IF(A12='Dados de entrada'!$E$2,PV('Dados de entrada'!$B$6,'Dados de entrada'!$B$10-'Dados de entrada'!$E$2+1,+L12*(-'Dados de entrada'!$E$3),,1)+L12*(1-'Dados de entrada'!$E$3)-M12-N12-P12-Q12,L12-M12-N12-P12-Q12)) -> 2837.7367 | S12: =IF(H12<>"",H12,"") -> 272 | T12: =IF(E12<>"",(-E12)/((1+'Dados de entrada'!$B$6)^(S12/30)),"") -> 490.97033 | U12: =IF(T12<>"",T12*S12,"") -> 133543.93 | V12: =IF(F12="","",-'Dados de entrada'!$B$2) -> -3000 | X12: =+Resumo!$E$12-Resumo!$E$20 -> 0 | Y12: =EDATE(Y11,1) -> 46484 | Z12: 30 | AA12: =AA11+Z12 -> 268 | AB12: =IF(A12<='Dados de entrada'!$B$18,'Dados de entrada'!$B$20,0) -> 3000 | AC12: =IF(OR(Resumo!$E$23>0,Resumo!$E$28>0,Resumo!$E$33>0),IF(AND(A12>'Dados de entrada'!$B$18,A12<='Dados de entrada'!$B$10),'Dados de entrada'!$B$21,0),IF(AND(A12>'Dados de entrada'!$B$18,A12<='Dados de entrada'!$B$10),'Dados de entrada'!$B$21,IF(A12<='Dados de entrada'!$B$18,X12,0))) -> 0 | AD12: =AC12/((1+'Dados de entrada'!$D$22)^($AA12/360)) -> 0 | AE12: =IF(A12<='Dados de entrada'!$B$27,'Dados de entrada'!$B$29,0) -> 0 | AF12: =IF(AND(A12>'Dados de entrada'!$B$27,A12<='Dados de entrada'!$B$10),'Dados de entrada'!$B$30,0) -> 0 | AG12: =AF12/((1+'Dados de entrada'!$D$31)^($AA12/360)) -> 0 | AH12: =IF(A12<='Dados de entrada'!$B$36,'Dados de entrada'!$B$38,0) -> 0 | AI12: =IF(AND(A12>'Dados de entrada'!$B$36,A12<='Dados de entrada'!$B$10),'Dados de entrada'!$B$39,0) -> 0 | AJ12: =AI12/((1+'Dados de entrada'!$D$40)^($AA12/360)) -> 0 | AK12: =IF(A12<='Dados de entrada'!$B$45,'Dados de entrada'!$B$47,0) -> 0 | AL12: =IF(AND(A12>'Dados de entrada'!$B$45,A12<='Dados de entrada'!$B$10),'Dados de entrada'!$B$48,0) -> 0 | AM12: =AL12/((1+'Dados de entrada'!$D$49)^($AA12/360)) -> 0 | AN12: =SUM(AB12:AC12,AE12:AF12,AH12:AI12,AK12:AL12) -> 3000
A13: =IF(A12="","",IF(A12+1<='Dados de entrada'!$B$10,A12+1,"")) -> 10 | B13: =IF(A13="","",DATE(YEAR(B12),MONTH(B12)+1,DAY(B12))) -> 46514 | C13: =IF(A13="","",30) -> 30 | D13: =IF(A13="","",F12*(1+'Dados de entrada'!$B$6)^(C13/30)) -> 23448.748 | E13: =IF(A13="","",-'Dados de entrada'!$J$20) -> -615.26348 | F13: =IF(A13="","",D13+E13) -> 22833.484 | G13: =IF(A13="","",F12-F13) -> 38.833774 | H13: =IF(A13="","",B13-$B$3) -> 302 | I13: =IF(A13="","",MIN(H13,365)*G13*'Dados de entrada'!$B$11+G13*'Dados de entrada'!$B$12) -> 1.1092479 | J13: =IF(A13="","",V13) -> -3000 | K13: =IF(A13="","",V13) -> -3000 | L13: =IF(A13="","",IF(A13<='Dados de entrada'!$J$2,-V12,-V12*(1-'Dados de entrada'!$J$3))) -> 3000 | M13: =IF(A13="","",L13*'Dados de entrada'!$E$4) -> 60.6 | N13: =IF(A13="","",IF(A13<='Dados de entrada'!$E$2,'Dados de entrada'!$E$13*'Dados de entrada'!$E$10/'Dados de entrada'!$B$10,'Dados de entrada'!$E$13*'Dados de entrada'!$E$10/'Dados de entrada'!$B$10*(1-'Dados de entrada'!$E$3))) -> 0 | O13: =IF(A13="","",IF(AND(A13='Dados de entrada'!$E$2),(O12*(1+'Dados de entrada'!$B$6)-L13)*(1-'Dados de entrada'!$E$3),IF(AND(A13<>'Dados de entrada'!$A$2),O12*(1+'Dados de entrada'!$B$6)^(C13/30)-L13,""))) -> 111335.15 | P13: =IF(A13="","",(O12*((1+'Dados de entrada'!$B$6)^(-DAYS360(B13,B12)/30)-1)-O12*((1+'Dados de entrada'!$H$10)^(-DAYS360(B13,B12)/360)-1))*4.65%) -> 101.49523 | Q13: =IF(E13<>"",'Dados de entrada'!$H$5-E13*'Dados de entrada'!$H$6,"") -> 0 | R13: =IF(A13="","",IF(A13='Dados de entrada'!$E$2,PV('Dados de entrada'!$B$6,'Dados de entrada'!$B$10-'Dados de entrada'!$E$2+1,+L13*(-'Dados de entrada'!$E$3),,1)+L13*(1-'Dados de entrada'!$E$3)-M13-N13-P13-Q13,L13-M13-N13-P13-Q13)) -> 2837.9048 | S13: =IF(H13<>"",H13,"") -> 302 | T13: =IF(E13<>"",(-E13)/((1+'Dados de entrada'!$B$6)^(S13/30)),"") -> 478.90103 | U13: =IF(T13<>"",T13*S13,"") -> 144628.11 | V13: =IF(F13="","",-'Dados de entrada'!$B$2) -> -3000 | X13: =+Resumo!$E$12-Resumo!$E$20 -> 0 | Y13: =EDATE(Y12,1) -> 46514 | Z13: 30 | AA13: =AA12+Z13 -> 298 | AB13: =IF(A13<='Dados de entrada'!$B$18,'Dados de entrada'!$B$20,0) -> 3000 | AC13: =IF(OR(Resumo!$E$23>0,Resumo!$E$28>0,Resumo!$E$33>0),IF(AND(A13>'Dados de entrada'!$B$18,A13<='Dados de entrada'!$B$10),'Dados de entrada'!$B$21,0),IF(AND(A13>'Dados de entrada'!$B$18,A13<='Dados de entrada'!$B$10),'Dados de entrada'!$B$21,IF(A13<='Dados de entrada'!$B$18,X13,0))) -> 0 | AD13: =AC13/((1+'Dados de entrada'!$D$22)^($AA13/360)) -> 0 | AE13: =IF(A13<='Dados de entrada'!$B$27,'Dados de entrada'!$B$29,0) -> 0 | AF13: =IF(AND(A13>'Dados de entrada'!$B$27,A13<='Dados de entrada'!$B$10),'Dados de entrada'!$B$30,0) -> 0 | AG13: =AF13/((1+'Dados de entrada'!$D$31)^($AA13/360)) -> 0 | AH13: =IF(A13<='Dados de entrada'!$B$36,'Dados de entrada'!$B$38,0) -> 0 | AI13: =IF(AND(A13>'Dados de entrada'!$B$36,A13<='Dados de entrada'!$B$10),'Dados de entrada'!$B$39,0) -> 0 | AJ13: =AI13/((1+'Dados de entrada'!$D$40)^($AA13/360)) -> 0 | AK13: =IF(A13<='Dados de entrada'!$B$45,'Dados de entrada'!$B$47,0) -> 0 | AL13: =IF(AND(A13>'Dados de entrada'!$B$45,A13<='Dados de entrada'!$B$10),'Dados de entrada'!$B$48,0) -> 0 | AM13: =AL13/((1+'Dados de entrada'!$D$49)^($AA13/360)) -> 0 | AN13: =SUM(AB13:AC13,AE13:AF13,AH13:AI13,AK13:AL13) -> 3000
A14: =IF(A13="","",IF(A13+1<='Dados de entrada'!$B$10,A13+1,"")) -> 11 | B14: =IF(A14="","",DATE(YEAR(B13),MONTH(B13)+1,DAY(B13))) -> 46545 | C14: =IF(A14="","",30) -> 30 | D14: =IF(A14="","",F13*(1+'Dados de entrada'!$B$6)^(C14/30)) -> 23408.935 | E14: =IF(A14="","",-'Dados de entrada'!$J$20) -> -615.26348 | F14: =IF(A14="","",D14+E14) -> 22793.672 | G14: =IF(A14="","",F13-F14) -> 39.812466 | H14: =IF(A14="","",B14-$B$3) -> 333 | I14: =IF(A14="","",MIN(H14,365)*G14*'Dados de entrada'!$B$11+G14*'Dados de entrada'!$B$12) -> 1.2384066 | J14: =IF(A14="","",V14) -> -3000 | K14: =IF(A14="","",V14) -> -3000 | L14: =IF(A14="","",IF(A14<='Dados de entrada'!$J$2,-V13,-V13*(1-'Dados de entrada'!$J$3))) -> 3000 | M14: =IF(A14="","",L14*'Dados de entrada'!$E$4) -> 60.6 | N14: =IF(A14="","",IF(A14<='Dados de entrada'!$E$2,'Dados de entrada'!$E$13*'Dados de entrada'!$E$10/'Dados de entrada'!$B$10,'Dados de entrada'!$E$13*'Dados de entrada'!$E$10/'Dados de entrada'!$B$10*(1-'Dados de entrada'!$E$3))) -> 0 | O14: =IF(A14="","",IF(AND(A14='Dados de entrada'!$E$2),(O13*(1+'Dados de entrada'!$B$6)-L14)*(1-'Dados de entrada'!$E$3),IF(AND(A14<>'Dados de entrada'!$A$2),O13*(1+'Dados de entrada'!$B$6)^(C14/30)-L14,""))) -> 111141.03 | P14: =IF(A14="","",(O13*((1+'Dados de entrada'!$B$6)^(-DAYS360(B14,B13)/30)-1)-O13*((1+'Dados de entrada'!$H$10)^(-DAYS360(B14,B13)/360)-1))*4.65%) -> 101.32291 | Q14: =IF(E14<>"",'Dados de entrada'!$H$5-E14*'Dados de entrada'!$H$6,"") -> 0 | R14: =IF(A14="","",IF(A14='Dados de entrada'!$E$2,PV('Dados de entrada'!$B$6,'Dados de entrada'!$B$10-'Dados de entrada'!$E$2+1,+L14*(-'Dados de entrada'!$E$3),,1)+L14*(1-'Dados de entrada'!$E$3)-M14-N14-P14-Q14,L14-M14-N14-P14-Q14)) -> 2838.0771 | S14: =IF(H14<>"",H14,"") -> 333 | T14: =IF(E14<>"",(-E14)/((1+'Dados de entrada'!$B$6)^(S14/30)),"") -> 466.74103 | U14: =IF(T14<>"",T14*S14,"") -> 155424.76 | V14: =IF(F14="","",-'Dados de entrada'!$B$2) -> -3000 | X14: =+Resumo!$E$12-Resumo!$E$20 -> 0 | Y14: =EDATE(Y13,1) -> 46545 | Z14: 30 | AA14: =AA13+Z14 -> 328 | AB14: =IF(A14<='Dados de entrada'!$B$18,'Dados de entrada'!$B$20,0) -> 3000 | AC14: =IF(OR(Resumo!$E$23>0,Resumo!$E$28>0,Resumo!$E$33>0),IF(AND(A14>'Dados de entrada'!$B$18,A14<='Dados de entrada'!$B$10),'Dados de entrada'!$B$21,0),IF(AND(A14>'Dados de entrada'!$B$18,A14<='Dados de entrada'!$B$10),'Dados de entrada'!$B$21,IF(A14<='Dados de entrada'!$B$18,X14,0))) -> 0 | AD14: =AC14/((1+'Dados de entrada'!$D$22)^($AA14/360)) -> 0 | AE14: =IF(A14<='Dados de entrada'!$B$27,'Dados de entrada'!$B$29,0) -> 0 | AF14: =IF(AND(A14>'Dados de entrada'!$B$27,A14<='Dados de entrada'!$B$10),'Dados de entrada'!$B$30,0) -> 0 | AG14: =AF14/((1+'Dados de entrada'!$D$31)^($AA14/360)) -> 0 | AH14: =IF(A14<='Dados de entrada'!$B$36,'Dados de entrada'!$B$38,0) -> 0 | AI14: =IF(AND(A14>'Dados de entrada'!$B$36,A14<='Dados de entrada'!$B$10),'Dados de entrada'!$B$39,0) -> 0 | AJ14: =AI14/((1+'Dados de entrada'!$D$40)^($AA14/360)) -> 0 | AK14: =IF(A14<='Dados de entrada'!$B$45,'Dados de entrada'!$B$47,0) -> 0 | AL14: =IF(AND(A14>'Dados de entrada'!$B$45,A14<='Dados de entrada'!$B$10),'Dados de entrada'!$B$48,0) -> 0 | AM14: =AL14/((1+'Dados de entrada'!$D$49)^($AA14/360)) -> 0 | AN14: =SUM(AB14:AC14,AE14:AF14,AH14:AI14,AK14:AL14) -> 3000
A15: =IF(A14="","",IF(A14+1<='Dados de entrada'!$B$10,A14+1,"")) -> 12 | B15: =IF(A15="","",DATE(YEAR(B14),MONTH(B14)+1,DAY(B14))) -> 46575 | C15: =IF(A15="","",30) -> 30 | D15: =IF(A15="","",F14*(1+'Dados de entrada'!$B$6)^(C15/30)) -> 23368.12 | E15: =IF(A15="","",-'Dados de entrada'!$J$20) -> -615.26348 | F15: =IF(A15="","",D15+E15) -> 22752.856 | G15: =IF(A15="","",F14-F15) -> 40.815822 | H15: =IF(A15="","",B15-$B$3) -> 363 | I15: =IF(A15="","",MIN(H15,365)*G15*'Dados de entrada'!$B$11+G15*'Dados de entrada'!$B$12) -> 1.3700239 | J15: =IF(A15="","",V15) -> -3000 | K15: =IF(A15="","",V15) -> -3000 | L15: =IF(A15="","",IF(A15<='Dados de entrada'!$J$2,-V14,-V14*(1-'Dados de entrada'!$J$3))) -> 3000 | M15: =IF(A15="","",L15*'Dados de entrada'!$E$4) -> 60.6 | N15: =IF(A15="","",IF(A15<='Dados de entrada'!$E$2,'Dados de entrada'!$E$13*'Dados de entrada'!$E$10/'Dados de entrada'!$B$10,'Dados de entrada'!$E$13*'Dados de entrada'!$E$10/'Dados de entrada'!$B$10*(1-'Dados de entrada'!$E$3))) -> 0 | O15: =IF(A15="","",IF(AND(A15='Dados de entrada'!$E$2),(O14*(1+'Dados de entrada'!$B$6)-L15)*(1-'Dados de entrada'!$E$3),IF(AND(A15<>'Dados de entrada'!$A$2),O14*(1+'Dados de entrada'!$B$6)^(C15/30)-L15,""))) -> 110942.01 | P15: =IF(A15="","",(O14*((1+'Dados de entrada'!$B$6)^(-DAYS360(B15,B14)/30)-1)-O14*((1+'Dados de entrada'!$H$10)^(-DAYS360(B15,B14)/360)-1))*4.65%) -> 101.14624 | Q15: =IF(E15<>"",'Dados de entrada'!$H$5-E15*'Dados de entrada'!$H$6,"") -> 0 | R15: =IF(A15="","",IF(A15='Dados de entrada'!$E$2,PV('Dados de entrada'!$B$6,'Dados de entrada'!$B$10-'Dados de entrada'!$E$2+1,+L15*(-'Dados de entrada'!$E$3),,1)+L15*(1-'Dados de entrada'!$E$3)-M15-N15-P15-Q15,L15-M15-N15-P15-Q15)) -> 2838.2538 | S15: =IF(H15<>"",H15,"") -> 363 | T15: =IF(E15<>"",(-E15)/((1+'Dados de entrada'!$B$6)^(S15/30)),"") -> 455.26735 | U15: =IF(T15<>"",T15*S15,"") -> 165262.05 | V15: =IF(F15="","",-'Dados de entrada'!$B$2) -> -3000 | X15: =+Resumo!$E$12-Resumo!$E$20 -> 0 | Y15: =EDATE(Y14,1) -> 46575 | Z15: 30 | AA15: =AA14+Z15 -> 358 | AB15: =IF(A15<='Dados de entrada'!$B$18,'Dados de entrada'!$B$20,0) -> 3000 | AC15: =IF(OR(Resumo!$E$23>0,Resumo!$E$28>0,Resumo!$E$33>0),IF(AND(A15>'Dados de entrada'!$B$18,A15<='Dados de entrada'!$B$10),'Dados de entrada'!$B$21,0),IF(AND(A15>'Dados de entrada'!$B$18,A15<='Dados de entrada'!$B$10),'Dados de entrada'!$B$21,IF(A15<='Dados de entrada'!$B$18,X15,0))) -> 0 | AD15: =AC15/((1+'Dados de entrada'!$D$22)^($AA15/360)) -> 0 | AE15: =IF(A15<='Dados de entrada'!$B$27,'Dados de entrada'!$B$29,0) -> 0 | AF15: =IF(AND(A15>'Dados de entrada'!$B$27,A15<='Dados de entrada'!$B$10),'Dados de entrada'!$B$30,0) -> 0 | AG15: =AF15/((1+'Dados de entrada'!$D$31)^($AA15/360)) -> 0 | AH15: =IF(A15<='Dados de entrada'!$B$36,'Dados de entrada'!$B$38,0) -> 0 | AI15: =IF(AND(A15>'Dados de entrada'!$B$36,A15<='Dados de entrada'!$B$10),'Dados de entrada'!$B$39,0) -> 0 | AJ15: =AI15/((1+'Dados de entrada'!$D$40)^($AA15/360)) -> 0 | AK15: =IF(A15<='Dados de entrada'!$B$45,'Dados de entrada'!$B$47,0) -> 0 | AL15: =IF(AND(A15>'Dados de entrada'!$B$45,A15<='Dados de entrada'!$B$10),'Dados de entrada'!$B$48,0) -> 0 | AM15: =AL15/((1+'Dados de entrada'!$D$49)^($AA15/360)) -> 0 | AN15: =SUM(AB15:AC15,AE15:AF15,AH15:AI15,AK15:AL15) -> 3000
A16: =IF(A15="","",IF(A15+1<='Dados de entrada'!$B$10,A15+1,"")) -> 13 | B16: =IF(A16="","",DATE(YEAR(B15),MONTH(B15)+1,DAY(B15))) -> 46606 | C16: =IF(A16="","",30) -> 30 | D16: =IF(A16="","",F15*(1+'Dados de entrada'!$B$6)^(C16/30)) -> 23326.275 | E16: =IF(A16="","",-'Dados de entrada'!$J$20) -> -615.26348 | F16: =IF(A16="","",D16+E16) -> 22711.012 | G16: =IF(A16="","",F15-F16) -> 41.844465 | H16: =IF(A16="","",B16-$B$3) -> 394 | I16: =IF(A16="","",MIN(H16,365)*G16*'Dados de entrada'!$B$11+G16*'Dados de entrada'!$B$12) -> 1.4114138 | J16: =IF(A16="","",V16) -> -3000 | K16: =IF(A16="","",V16) -> -3000 | L16: =IF(A16="","",IF(A16<='Dados de entrada'!$J$2,-V15,-V15*(1-'Dados de entrada'!$J$3))) -> 3000 | M16: =IF(A16="","",L16*'Dados de entrada'!$E$4) -> 60.6 | N16: =IF(A16="","",IF(A16<='Dados de entrada'!$E$2,'Dados de entrada'!$E$13*'Dados de entrada'!$E$10/'Dados de entrada'!$B$10,'Dados de entrada'!$E$13*'Dados de entrada'!$E$10/'Dados de entrada'!$B$10*(1-'Dados de entrada'!$E$3))) -> 0 | O16: =IF(A16="","",IF(AND(A16='Dados de entrada'!$E$2),(O15*(1+'Dados de entrada'!$B$6)-L16)*(1-'Dados de entrada'!$E$3),IF(AND(A16<>'Dados de entrada'!$A$2),O15*(1+'Dados de entrada'!$B$6)^(C16/30)-L16,""))) -> 110737.98 | P16: =IF(A16="","",(O15*((1+'Dados de entrada'!$B$6)^(-DAYS360(B16,B15)/30)-1)-O15*((1+'Dados de entrada'!$H$10)^(-DAYS360(B16,B15)/360)-1))*4.65%) -> 100.96512 | Q16: =IF(E16<>"",'Dados de entrada'!$H$5-E16*'Dados de entrada'!$H$6,"") -> 0 | R16: =IF(A16="","",IF(A16='Dados de entrada'!$E$2,PV('Dados de entrada'!$B$6,'Dados de entrada'!$B$10-'Dados de entrada'!$E$2+1,+L16*(-'Dados de entrada'!$E$3),,1)+L16*(1-'Dados de entrada'!$E$3)-M16-N16-P16-Q16,L16-M16-N16-P16-Q16)) -> 2838.4349 | S16: =IF(H16<>"",H16,"") -> 394 | T16: =IF(E16<>"",(-E16)/((1+'Dados de entrada'!$B$6)^(S16/30)),"") -> 443.70745 | U16: =IF(T16<>"",T16*S16,"") -> 174820.73 | V16: =IF(F16="","",-'Dados de entrada'!$B$2) -> -3000 | X16: =+Resumo!$E$12-Resumo!$E$20 -> 0 | Y16: =EDATE(Y15,1) -> 46606 | Z16: 30 | AA16: =AA15+Z16 -> 388 | AB16: =IF(A16<='Dados de entrada'!$B$18,'Dados de entrada'!$B$20,0) -> 3000 | AC16: =IF(OR(Resumo!$E$23>0,Resumo!$E$28>0,Resumo!$E$33>0),IF(AND(A16>'Dados de entrada'!$B$18,A16<='Dados de entrada'!$B$10),'Dados de entrada'!$B$21,0),IF(AND(A16>'Dados de entrada'!$B$18,A16<='Dados de entrada'!$B$10),'Dados de entrada'!$B$21,IF(A16<='Dados de entrada'!$B$18,X16,0))) -> 0 | AD16: =AC16/((1+'Dados de entrada'!$D$22)^($AA16/360)) -> 0 | AE16: =IF(A16<='Dados de entrada'!$B$27,'Dados de entrada'!$B$29,0) -> 0 | AF16: =IF(AND(A16>'Dados de entrada'!$B$27,A16<='Dados de entrada'!$B$10),'Dados de entrada'!$B$30,0) -> 0 | AG16: =AF16/((1+'Dados de entrada'!$D$31)^($AA16/360)) -> 0 | AH16: =IF(A16<='Dados de entrada'!$B$36,'Dados de entrada'!$B$38,0) -> 0 | AI16: =IF(AND(A16>'Dados de entrada'!$B$36,A16<='Dados de entrada'!$B$10),'Dados de entrada'!$B$39,0) -> 0 | AJ16: =AI16/((1+'Dados de entrada'!$D$40)^($AA16/360)) -> 0 | AK16: =IF(A16<='Dados de entrada'!$B$45,'Dados de entrada'!$B$47,0) -> 0 | AL16: =IF(AND(A16>'Dados de entrada'!$B$45,A16<='Dados de entrada'!$B$10),'Dados de entrada'!$B$48,0) -> 0 | AM16: =AL16/((1+'Dados de entrada'!$D$49)^($AA16/360)) -> 0 | AN16: =SUM(AB16:AC16,AE16:AF16,AH16:AI16,AK16:AL16) -> 3000
A17: =IF(A16="","",IF(A16+1<='Dados de entrada'!$B$10,A16+1,"")) -> 14 | B17: =IF(A17="","",DATE(YEAR(B16),MONTH(B16)+1,DAY(B16))) -> 46637 | C17: =IF(A17="","",30) -> 30 | D17: =IF(A17="","",F16*(1+'Dados de entrada'!$B$6)^(C17/30)) -> 23283.376 | E17: =IF(A17="","",-'Dados de entrada'!$J$20) -> -615.26348 | F17: =IF(A17="","",D17+E17) -> 22668.113 | G17: =IF(A17="","",F16-F17) -> 42.899032 | H17: =IF(A17="","",B17-$B$3) -> 425 | I17: =IF(A17="","",MIN(H17,365)*G17*'Dados de entrada'!$B$11+G17*'Dados de entrada'!$B$12) -> 1.4469844 | J17: =IF(A17="","",V17) -> -3000 | K17: =IF(A17="","",V17) -> -3000 | L17: =IF(A17="","",IF(A17<='Dados de entrada'!$J$2,-V16,-V16*(1-'Dados de entrada'!$J$3))) -> 3000 | M17: =IF(A17="","",L17*'Dados de entrada'!$E$4) -> 60.6 | N17: =IF(A17="","",IF(A17<='Dados de entrada'!$E$2,'Dados de entrada'!$E$13*'Dados de entrada'!$E$10/'Dados de entrada'!$B$10,'Dados de entrada'!$E$13*'Dados de entrada'!$E$10/'Dados de entrada'!$B$10*(1-'Dados de entrada'!$E$3))) -> 0 | O17: =IF(A17="","",IF(AND(A17='Dados de entrada'!$E$2),(O16*(1+'Dados de entrada'!$B$6)-L17)*(1-'Dados de entrada'!$E$3),IF(AND(A17<>'Dados de entrada'!$A$2),O16*(1+'Dados de entrada'!$B$6)^(C17/30)-L17,""))) -> 110528.81 | P17: =IF(A17="","",(O16*((1+'Dados de entrada'!$B$6)^(-DAYS360(B17,B16)/30)-1)-O16*((1+'Dados de entrada'!$H$10)^(-DAYS360(B17,B16)/360)-1))*4.65%) -> 100.77944 | Q17: =IF(E17<>"",'Dados de entrada'!$H$5-E17*'Dados de entrada'!$H$6,"") -> 0 | R17: =IF(A17="","",IF(A17='Dados de entrada'!$E$2,PV('Dados de entrada'!$B$6,'Dados de entrada'!$B$10-'Dados de entrada'!$E$2+1,+L17*(-'Dados de entrada'!$E$3),,1)+L17*(1-'Dados de entrada'!$E$3)-M17-N17-P17-Q17,L17-M17-N17-P17-Q17)) -> 2838.6206 | S17: =IF(H17<>"",H17,"") -> 425 | T17: =IF(E17<>"",(-E17)/((1+'Dados de entrada'!$B$6)^(S17/30)),"") -> 432.44107 | U17: =IF(T17<>"",T17*S17,"") -> 183787.45 | V17: =IF(F17="","",-'Dados de entrada'!$B$2) -> -3000 | X17: =+Resumo!$E$12-Resumo!$E$20 -> 0 | Y17: =EDATE(Y16,1) -> 46637 | Z17: 30 | AA17: =AA16+Z17 -> 418 | AB17: =IF(A17<='Dados de entrada'!$B$18,'Dados de entrada'!$B$20,0) -> 3000 | AC17: =IF(OR(Resumo!$E$23>0,Resumo!$E$28>0,Resumo!$E$33>0),IF(AND(A17>'Dados de entrada'!$B$18,A17<='Dados de entrada'!$B$10),'Dados de entrada'!$B$21,0),IF(AND(A17>'Dados de entrada'!$B$18,A17<='Dados de entrada'!$B$10),'Dados de entrada'!$B$21,IF(A17<='Dados de entrada'!$B$18,X17,0))) -> 0 | AD17: =AC17/((1+'Dados de entrada'!$D$22)^($AA17/360)) -> 0 | AE17: =IF(A17<='Dados de entrada'!$B$27,'Dados de entrada'!$B$29,0) -> 0 | AF17: =IF(AND(A17>'Dados de entrada'!$B$27,A17<='Dados de entrada'!$B$10),'Dados de entrada'!$B$30,0) -> 0 | AG17: =AF17/((1+'Dados de entrada'!$D$31)^($AA17/360)) -> 0 | AH17: =IF(A17<='Dados de entrada'!$B$36,'Dados de entrada'!$B$38,0) -> 0 | AI17: =IF(AND(A17>'Dados de entrada'!$B$36,A17<='Dados de entrada'!$B$10),'Dados de entrada'!$B$39,0) -> 0 | AJ17: =AI17/((1+'Dados de entrada'!$D$40)^($AA17/360)) -> 0 | AK17: =IF(A17<='Dados de entrada'!$B$45,'Dados de entrada'!$B$47,0) -> 0 | AL17: =IF(AND(A17>'Dados de entrada'!$B$45,A17<='Dados de entrada'!$B$10),'Dados de entrada'!$B$48,0) -> 0 | AM17: =AL17/((1+'Dados de entrada'!$D$49)^($AA17/360)) -> 0 | AN17: =SUM(AB17:AC17,AE17:AF17,AH17:AI17,AK17:AL17) -> 3000
